<?xml version="1.0" encoding="utf-8"?>
<!-- =================================================================================== -->
<!-- |    This document was autogenerated by xacro from /home/pfe/Desktop/catkin_ws/src/markhor/markhor_description/urdf/markhor.urdf.xacro | -->
<!-- |    EDITING THIS FILE BY HAND IS NOT RECOMMENDED                                 | -->
<!-- =================================================================================== -->
<robot name="markhor" xmlns:xi="http://www.w3.org/2001/XInclude">
  <link name="base_footprint"/>
  <link name="base_link"/>
  <link name="base_body">
    <visual>
      <geometry>
        <mesh filename="package://markhor_description/meshes/mk_link_base.stl"/>
      </geometry>
      <origin rpy="0 3.14159265359 0" xyz="0 0 0"/>
    </visual>
    <collision>
      <geometry>
        <mesh filename="package://markhor_description/meshes/mk_link_base.stl"/>
      </geometry>
      <origin rpy="0 3.14159265359 0" xyz="0 0 0"/>
    </collision>
    <inertial>
      <mass value="26.111"/>
      <origin rpy="0 0 0" xyz="-0.00002529 0.00000008 -0.06049447"/>
      <inertia ixx="0.385006414" ixy="0.0000696244868" ixz="-0.000181517937" iyy="0.624959190" iyz="0.000000162897534" izz="0.798949961"/>
    </inertial>
  </link>
  <joint name="base_link_j" type="fixed">
    <origin rpy="0 0 0" xyz="0 0 -0.085"/>
    <parent link="base_link"/>
    <child link="base_footprint"/>
  </joint>
  <joint name="base_body_j" type="fixed">
    <parent link="base_link"/>
    <child link="base_body"/>
  </joint>
  <link name="flipper_fl">
    <visual>
      <geometry>
        <mesh filename="package://markhor_description/meshes/mk_flip.stl"/>
      </geometry>
      <origin rpy="0 0 0" xyz="0 0 0"/>
    </visual>
    <collision>
      <geometry>
        <mesh filename="package://markhor_description/meshes/mk_flip.stl"/>
      </geometry>
      <origin rpy="0 0 0" xyz="0 0 0"/>
      <surface>
        <friction>
          <ode>
            <mu>0.65</mu>
            <mu2>0.85</mu2>
          </ode>
        </friction>
        <contact>
          <ode/>
        </contact>
      </surface>
    </collision>
    <max_contacts>20</max_contacts>
    <inertial>
      <mass value="6.9"/>
      <origin rpy="0 0 0" xyz="0 0.116 0"/>
      <inertia ixx="0.268046334" ixy="0.000960466048" ixz="0.000262590776" iyy="0.0573569235" iyz="0.0000904647719" izz="0.232597105"/>
    </inertial>
  </link>
  <link name="flipper_fl_motor">
    <inertial>
      <mass value="0.0001"/>
      <origin rpy="0 0 0" xyz="0 0 0"/>
      <inertia ixx="0.001" ixy="0" ixz="0" iyy="0.001" iyz="0" izz="0.001"/>
    </inertial>
  </link>
  <joint name="flipper_fl_j" type="revolute">
    <parent link="base_link"/>
    <child link="flipper_fl"/>
    <axis rpy="0 0 0" xyz="1 0 0"/>
    <origin rpy="1.57079632679 0 -1.57079632679" xyz="0.31115 0.2230283 0.0531876"/>
    <limit effort="184" lower="-3.14159265359" upper="0" velocity="16.75"/>
    <dynamics damping="150"/>
  </joint>
  <joint name="flipper_fl_motor_j" type="continuous">
    <parent link="flipper_fl"/>
    <child link="flipper_fl_motor"/>
    <axis rpy="0 0 0" xyz="1 0 0"/>
    <limit effort="94.5" velocity="5.34"/>
  </joint>
  <transmission name="flipper_fl_trans">
    <type>transmission_interface/SimpleTransmission</type>
    <joint name="flipper_fl_j">
      <hardwareInterface>hardware_interface/EffortJointInterface</hardwareInterface>
    </joint>
    <actuator name="flipper_fl_actuator">
      <mechanicalReduction>1</mechanicalReduction>
    </actuator>
  </transmission>
  <transmission name="flipper_fl_track_trans" type="SimpleTransmission">
    <type>transmission_interface/SimpleTransmission</type>
    <joint name="flipper_fl_motor_j">
      <hardwareInterface>hardware_interface/VelocityJointInterface</hardwareInterface>
    </joint>
    <actuator name="flipper_fl_track_motor">
      <mechanicalReduction>1</mechanicalReduction>
    </actuator>
  </transmission>
  <link name="flipper_fr">
    <visual>
      <geometry>
        <mesh filename="package://markhor_description/meshes/mk_flip.stl"/>
      </geometry>
      <origin rpy="0 0 0" xyz="0 0 0"/>
    </visual>
    <collision>
      <geometry>
        <mesh filename="package://markhor_description/meshes/mk_flip.stl"/>
      </geometry>
      <origin rpy="0 0 0" xyz="0 0 0"/>
      <surface>
        <friction>
          <ode>
            <mu>0.65</mu>
            <mu2>0.85</mu2>
          </ode>
        </friction>
        <contact>
          <ode/>
        </contact>
      </surface>
    </collision>
    <max_contacts>20</max_contacts>
    <inertial>
      <mass value="6.9"/>
      <origin rpy="0 0 0" xyz="0 0.116 0"/>
      <inertia ixx="0.268046334" ixy="0.000960466048" ixz="0.000262590776" iyy="0.0573569235" iyz="0.0000904647719" izz="0.232597105"/>
    </inertial>
  </link>
  <link name="flipper_fr_motor">
    <inertial>
      <mass value="0.0001"/>
      <origin rpy="0 0 0" xyz="0 0 0"/>
      <inertia ixx="0.001" ixy="0" ixz="0" iyy="0.001" iyz="0" izz="0.001"/>
    </inertial>
  </link>
  <joint name="flipper_fr_j" type="revolute">
    <parent link="base_link"/>
    <child link="flipper_fr"/>
    <axis rpy="0 0 0" xyz="1 0 0"/>
    <origin rpy="1.57079632679 0 -1.57079632679" xyz="0.31115 -0.2230283 0.0531876"/>
    <limit effort="184" lower="-3.14159265359" upper="0" velocity="16.75"/>
    <dynamics damping="150"/>
  </joint>
  <joint name="flipper_fr_motor_j" type="continuous">
    <parent link="flipper_fr"/>
    <child link="flipper_fr_motor"/>
    <axis rpy="0 0 0" xyz="1 0 0"/>
    <limit effort="94.5" velocity="5.34"/>
  </joint>
  <transmission name="flipper_fr_trans">
    <type>transmission_interface/SimpleTransmission</type>
    <joint name="flipper_fr_j">
      <hardwareInterface>hardware_interface/EffortJointInterface</hardwareInterface>
    </joint>
    <actuator name="flipper_fr_actuator">
      <mechanicalReduction>1</mechanicalReduction>
    </actuator>
  </transmission>
  <transmission name="flipper_fr_track_trans" type="SimpleTransmission">
    <type>transmission_interface/SimpleTransmission</type>
    <joint name="flipper_fr_motor_j">
      <hardwareInterface>hardware_interface/VelocityJointInterface</hardwareInterface>
    </joint>
    <actuator name="flipper_fr_track_motor">
      <mechanicalReduction>1</mechanicalReduction>
    </actuator>
  </transmission>
  <link name="flipper_rl">
    <visual>
      <geometry>
        <mesh filename="package://markhor_description/meshes/mk_flip.stl"/>
      </geometry>
      <origin rpy="0 0 0" xyz="0 0 0"/>
    </visual>
    <collision>
      <geometry>
        <mesh filename="package://markhor_description/meshes/mk_flip.stl"/>
      </geometry>
      <origin rpy="0 0 0" xyz="0 0 0"/>
      <surface>
        <friction>
          <ode>
            <mu>0.65</mu>
            <mu2>0.85</mu2>
          </ode>
        </friction>
        <contact>
          <ode/>
        </contact>
      </surface>
    </collision>
    <max_contacts>20</max_contacts>
    <inertial>
      <mass value="6.9"/>
      <origin rpy="0 0 0" xyz="0 0.116 0"/>
      <inertia ixx="0.268046334" ixy="0.000960466048" ixz="0.000262590776" iyy="0.0573569235" iyz="0.0000904647719" izz="0.232597105"/>
    </inertial>
  </link>
  <link name="flipper_rl_motor">
    <inertial>
      <mass value="0.0001"/>
      <origin rpy="0 0 0" xyz="0 0 0"/>
      <inertia ixx="0.001" ixy="0" ixz="0" iyy="0.001" iyz="0" izz="0.001"/>
    </inertial>
  </link>
  <joint name="flipper_rl_j" type="revolute">
    <parent link="base_link"/>
    <child link="flipper_rl"/>
    <axis rpy="0 0 0" xyz="1 0 0"/>
    <origin rpy="1.57079632679 0 1.57079632679" xyz="-0.31115 0.2230283 0.0531876"/>
    <limit effort="184" lower="-3.14159265359" upper="0" velocity="16.75"/>
    <dynamics damping="150"/>
  </joint>
  <joint name="flipper_rl_motor_j" type="continuous">
    <parent link="flipper_rl"/>
    <child link="flipper_rl_motor"/>
    <axis rpy="0 0 0" xyz="1 0 0"/>
    <limit effort="94.5" velocity="5.34"/>
  </joint>
  <transmission name="flipper_rl_trans">
    <type>transmission_interface/SimpleTransmission</type>
    <joint name="flipper_rl_j">
      <hardwareInterface>hardware_interface/EffortJointInterface</hardwareInterface>
    </joint>
    <actuator name="flipper_rl_actuator">
      <mechanicalReduction>1</mechanicalReduction>
    </actuator>
  </transmission>
  <transmission name="flipper_rl_track_trans" type="SimpleTransmission">
    <type>transmission_interface/SimpleTransmission</type>
    <joint name="flipper_rl_motor_j">
      <hardwareInterface>hardware_interface/VelocityJointInterface</hardwareInterface>
    </joint>
    <actuator name="flipper_rl_track_motor">
      <mechanicalReduction>1</mechanicalReduction>
    </actuator>
  </transmission>
  <link name="flipper_rr">
    <visual>
      <geometry>
        <mesh filename="package://markhor_description/meshes/mk_flip.stl"/>
      </geometry>
      <origin rpy="0 0 0" xyz="0 0 0"/>
    </visual>
    <collision>
      <geometry>
        <mesh filename="package://markhor_description/meshes/mk_flip.stl"/>
      </geometry>
      <origin rpy="0 0 0" xyz="0 0 0"/>
      <surface>
        <friction>
          <ode>
            <mu>0.65</mu>
            <mu2>0.85</mu2>
          </ode>
        </friction>
        <contact>
          <ode/>
        </contact>
      </surface>
    </collision>
    <max_contacts>20</max_contacts>
    <inertial>
      <mass value="6.9"/>
      <origin rpy="0 0 0" xyz="0 0.116 0"/>
      <inertia ixx="0.268046334" ixy="0.000960466048" ixz="0.000262590776" iyy="0.0573569235" iyz="0.0000904647719" izz="0.232597105"/>
    </inertial>
  </link>
  <link name="flipper_rr_motor">
    <inertial>
      <mass value="0.0001"/>
      <origin rpy="0 0 0" xyz="0 0 0"/>
      <inertia ixx="0.001" ixy="0" ixz="0" iyy="0.001" iyz="0" izz="0.001"/>
    </inertial>
  </link>
  <joint name="flipper_rr_j" type="revolute">
    <parent link="base_link"/>
    <child link="flipper_rr"/>
    <axis rpy="0 0 0" xyz="1 0 0"/>
    <origin rpy="1.57079632679 0 1.57079632679" xyz="-0.31115 -0.2230283 0.0531876"/>
    <limit effort="184" lower="-3.14159265359" upper="0" velocity="16.75"/>
    <dynamics damping="150"/>
  </joint>
  <joint name="flipper_rr_motor_j" type="continuous">
    <parent link="flipper_rr"/>
    <child link="flipper_rr_motor"/>
    <axis rpy="0 0 0" xyz="1 0 0"/>
    <limit effort="94.5" velocity="5.34"/>
  </joint>
  <transmission name="flipper_rr_trans">
    <type>transmission_interface/SimpleTransmission</type>
    <joint name="flipper_rr_j">
      <hardwareInterface>hardware_interface/EffortJointInterface</hardwareInterface>
    </joint>
    <actuator name="flipper_rr_actuator">
      <mechanicalReduction>1</mechanicalReduction>
    </actuator>
  </transmission>
  <transmission name="flipper_rr_track_trans" type="SimpleTransmission">
    <type>transmission_interface/SimpleTransmission</type>
    <joint name="flipper_rr_motor_j">
      <hardwareInterface>hardware_interface/VelocityJointInterface</hardwareInterface>
    </joint>
    <actuator name="flipper_rr_track_motor">
      <mechanicalReduction>1</mechanicalReduction>
    </actuator>
  </transmission>
  <link name="front_cam">
    <inertial>
      <mass value="0.0001"/>
      <origin rpy="0 0 0" xyz="0 0 0"/>
      <inertia ixx="0.001" ixy="0" ixz="0" iyy="0.001" iyz="0" izz="0.001"/>
    </inertial>
  </link>
  <joint name="front_cam_j" type="fixed">
    <parent link="base_link"/>
    <child link="front_cam"/>
    <origin rpy="0 0 0" xyz="0.35864800 0 0.03810000"/>
  </joint>
  <gazebo reference="front_cam">
    <sensor name="front_cam_camera" type="depth">
      <update_rate>60</update_rate>
      <camera>
        <horizontal_fov>1.047198</horizontal_fov>
        <image>
          <width>640</width>
          <height>400</height>
          <format>R8G8B8</format>
        </image>
        <clip>
          <near>0.25</near>
          <far>1.5</far>
        </clip>
      </camera>
      <plugin filename="libgazebo_ros_openni_kinect.so" name="front_cam_controller">
        <baseline>0.2</baseline>
        <alwaysOn>true</alwaysOn>
        <updateRate>1.0</updateRate>
        <cameraName>markhor/front_cam_ir</cameraName>
        <imageTopicName>/markhor/front_cam/color/image_raw</imageTopicName>
        <cameraInfoTopicName>/markhor/front_cam/color/camera_info</cameraInfoTopicName>
        <depthImageTopicName>/markhor/front_cam/depth/image_raw</depthImageTopicName>
        <depthImageInfoTopicName>/markhor/front_cam/depth/camera_info</depthImageInfoTopicName>
        <pointCloudTopicName>/markhor/front_cam/depth/points</pointCloudTopicName>
        <frameName>front_cam</frameName>
        <pointCloudCutoff>0.5</pointCloudCutoff>
        <pointCloudCutoffMax>3.0</pointCloudCutoffMax>
        <distortionK1>0.00000001</distortionK1>
        <distortionK2>0.00000001</distortionK2>
        <distortionK3>0.00000001</distortionK3>
        <distortionT1>0.00000001</distortionT1>
        <distortionT2>0.00000001</distortionT2>
        <CxPrime>0</CxPrime>
        <Cx>0</Cx>
        <Cy>0</Cy>
        <focalLength>0</focalLength>
        <hackBaseline>0</hackBaseline>
      </plugin>
    </sensor>
  </gazebo>
  <link name="rear_cam">
    <inertial>
      <mass value="0.0001"/>
      <origin rpy="0 0 0" xyz="0 0 0"/>
      <inertia ixx="0.001" ixy="0" ixz="0" iyy="0.001" iyz="0" izz="0.001"/>
    </inertial>
  </link>
  <joint name="rear_cam_j" type="fixed">
    <parent link="base_link"/>
    <child link="rear_cam"/>
    <origin rpy="0 0 3.14159265359" xyz="-0.35864800 0 0.03810000"/>
  </joint>
  <gazebo reference="rear_cam">
    <sensor name="rear_cam_camera" type="depth">
      <update_rate>60</update_rate>
      <camera>
        <horizontal_fov>1.047198</horizontal_fov>
        <image>
          <width>640</width>
          <height>400</height>
          <format>R8G8B8</format>
        </image>
        <clip>
          <near>0.25</near>
          <far>1.5</far>
        </clip>
      </camera>
      <plugin filename="libgazebo_ros_openni_kinect.so" name="rear_cam_controller">
        <baseline>0.2</baseline>
        <alwaysOn>true</alwaysOn>
        <updateRate>1.0</updateRate>
        <cameraName>markhor/rear_cam_ir</cameraName>
        <imageTopicName>/markhor/rear_cam/color/image_raw</imageTopicName>
        <cameraInfoTopicName>/markhor/rear_cam/color/camera_info</cameraInfoTopicName>
        <depthImageTopicName>/markhor/rear_cam/depth/image_raw</depthImageTopicName>
        <depthImageInfoTopicName>/markhor/rear_cam/depth/camera_info</depthImageInfoTopicName>
        <pointCloudTopicName>/markhor/rear_cam/depth/points</pointCloudTopicName>
        <frameName>rear_cam</frameName>
        <pointCloudCutoff>0.5</pointCloudCutoff>
        <pointCloudCutoffMax>3.0</pointCloudCutoffMax>
        <distortionK1>0.00000001</distortionK1>
        <distortionK2>0.00000001</distortionK2>
        <distortionK3>0.00000001</distortionK3>
        <distortionT1>0.00000001</distortionT1>
        <distortionT2>0.00000001</distortionT2>
        <CxPrime>0</CxPrime>
        <Cx>0</Cx>
        <Cy>0</Cy>
        <focalLength>0</focalLength>
        <hackBaseline>0</hackBaseline>
      </plugin>
    </sensor>
  </gazebo>
  <link name="arm_root">
    <inertial>
      <mass value="0.0001"/>
      <origin rpy="0 0 0" xyz="0 0 0"/>
      <inertia ixx="0.001" ixy="0" ixz="0" iyy="0.001" iyz="0" izz="0.001"/>
    </inertial>
  </link>
  <joint name="arm_root_j" type="fixed">
    <parent link="base_link"/>
    <child link="arm_root"/>
    <origin rpy="0 0 0" xyz="0.17394875 0 0.12291060"/>
  </joint>
  <!-- z_offset: distance between base plate and laser center (= center of mesh) -->
  <link name="laser_mount_link">
    <inertial>
      <mass value="0.001"/>
      <origin xyz="0 0 0"/>
      <inertia ixx="0.000001" ixy="0.0" ixz="0.0" iyy="0.000001" iyz="0.0" izz="0.000001"/>
    </inertial>
  </link>
  <joint name="laser_joint" type="fixed">
    <parent link="laser_mount_link"/>
    <child link="laser"/>
    <origin rpy="0 0 0" xyz="0 0 0.06296"/>
  </joint>
  <link name="laser">
    <visual>
      <geometry>
        <mesh filename="package://sick_tim/meshes/sick_tim551.stl"/>
      </geometry>
      <material name="blue">
        <color rgba="0 0 1 1"/>
      </material>
    </visual>
    <collision>
      <geometry>
        <mesh filename="package://sick_tim/meshes/sick_tim551.stl"/>
      </geometry>
    </collision>
    <inertial>
      <mass value="0.25"/>
      <origin xyz="0 0 -0.026"/>
      <inertia ixx="0.0002290832417" ixy="0.0" ixz="0.0" iyy="0.0002290832417" iyz="0.0" izz="0.00014999994"/>
    </inertial>
  </link>
  <gazebo reference="laser">
    <material value="Gazebo/Blue"/>
    <sensor name="laser" type="ray">
      <always_on>true</always_on>
      <update_rate>15.0</update_rate>
      <pose>0 0 0 0 0 0</pose>
      <visualize>false</visualize>
      <ray>
        <scan>
          <horizontal>
            <samples>271</samples>
            <resolution>1</resolution>
            <min_angle>-2.357</min_angle>
            <max_angle>2.357</max_angle>
          </horizontal>
        </scan>
        <range>
          <min>0.05</min>
          <max>10</max>
          <resolution>0.01</resolution>
        </range>
      </ray>
      <plugin filename="libgazebo_ros_laser.so" name="gazebo_ros_laser_controller">
        <gaussianNoise>0.005</gaussianNoise>
        <alwaysOn>true</alwaysOn>
        <updateRate>15.0</updateRate>
        <topicName>scan</topicName>
        <frameName>laser</frameName>
      </plugin>
    </sensor>
  </gazebo>
  <joint name="laser_mount_link_j" type="fixed">
    <parent link="base_link"/>
    <child link="laser_mount_link"/>
    <origin rpy="0 0 0" xyz="0.32034017 0 0.1393156"/>
  </joint>
  <gazebo>
    <plugin filename="libgazebo_ros_control.so" name="gazebo_ros_control">
      <robotNamespace>/markhor</robotNamespace>
    </plugin>
    <!-- <plugin name="imu_controller" filename="libhector_gazebo_ros_imu.so">
      <robotNamespace>$(arg robot_namespace)</robotNamespace>
      <updateRate>50.0</updateRate>
      <bodyName>${prefix}_link_base</bodyName>
      <topicName>imu/data</topicName>
      <accelDrift>0.005 0.005 0.005</accelDrift>
      <accelGaussianNoise>0.005 0.005 0.005</accelGaussianNoise>
      <rateDrift>0.005 0.005 0.005 </rateDrift>
      <rateGaussianNoise>0.005 0.005 0.005 </rateGaussianNoise>
      <headingDrift>0.005</headingDrift>
      <headingGaussianNoise>0.005</headingGaussianNoise>
    </plugin> -->
    <plugin filename="libSimpleTrackedVehiclePlugin.so" name="simple_tracked_vehicle">
      <body>base_link</body>
      <left_track>flipper_fl</left_track>
      <right_track>flipper_fr</right_track>
      <left_flipper>flipper_rl</left_flipper>
      <right_flipper>flipper_rr</right_flipper>
      <track_mu>0.65</track_mu>
      <track_mu2>0.85</track_mu2>
      <tracks_separation>0.2230283 * 2</tracks_separation>
      <robot_namespace>markhor</robot_namespace>
    </plugin>
    <plugin filename="libKeysToCmdVelPlugin.so" name="keyboard_control">
      <publish_as_twist>true</publish_as_twist>
      <cmd_vel_topic>~/markhor/cmd_vel_twist</cmd_vel_topic>
    </plugin>
  </gazebo>
</robot>
