<?xml version="1.0" encoding="utf-8"?>
<!-- =================================================================================== -->
<!-- |    This document was autogenerated by xacro from /home/pfe/Desktop/catkin_ws/src/ovis_description/urdf/ovis_standalone.xacro | -->
<!-- |    EDITING THIS FILE BY HAND IS NOT RECOMMENDED                                 | -->
<!-- =================================================================================== -->
<!-- OVIS 6DOF spherical wrist robotic arm -->
<robot name="ovis" xmlns:body="http://playerstage.sourceforge.net/gazebo/xmlschema/#body" xmlns:controller="http://playerstage.sourceforge.net/gazebo/xmlschema/#controller" xmlns:gazebo="http://playerstage.sourceforge.net/gazebo/xmlschema/#gz" xmlns:geom="http://playerstage.sourceforge.net/gazebo/xmlschema/#geom" xmlns:interface="http://playerstage.sourceforge.net/gazebo/xmlschema/#interface" xmlns:joint="http://playerstage.sourceforge.net/gazebo/xmlschema/#joint" xmlns:model="http://playerstage.sourceforge.net/gazebo/xmlschema/#model" xmlns:physics="http://playerstage.sourceforge.net/gazebo/xmlschema/#physics" xmlns:renderable="http://playerstage.sourceforge.net/gazebo/xmlschema/#renderable" xmlns:rendering="http://playerstage.sourceforge.net/gazebo/xmlschema/#rendering" xmlns:sensor="http://playerstage.sourceforge.net/gazebo/xmlschema/#sensor" xmlns:xi="http://www.w3.org/2001/XInclude">
  <gazebo reference="ovis_link_base">
    <material>Gazebo/Red</material>
  </gazebo>
  <gazebo reference="ovis_link_1">
    <material>Gazebo/Red</material>
  </gazebo>
  <gazebo reference="ovis_link_2">
    <material>Gazebo/Red</material>
  </gazebo>
  <gazebo reference="ovis_link_3">
    <material>Gazebo/Red</material>
  </gazebo>
  <gazebo reference="ovis_link_4">
    <material>Gazebo/Red</material>
  </gazebo>
  <gazebo reference="ovis_link_5">
    <material>Gazebo/Red</material>
  </gazebo>
  <gazebo reference="ovis_link_6">
    <material>Gazebo/Red</material>
  </gazebo>
  <gazebo reference="ovis_camera">
    <material>Gazebo/Green</material>
    <sensor name="pt_grey_chameleon" type="camera">
      <update_rate>30.0</update_rate>
      <camera name="head">
        <horizontal_fov>1.3962634</horizontal_fov>
        <image>
          <width>1296</width>
          <height>964</height>
          <format>R8G8B8</format>
        </image>
        <clip>
          <near>0.01</near>
          <far>100</far>
        </clip>
      </camera>
      <plugin filename="libgazebo_ros_camera.so" name="camera_controller">
        <alwaysOn>true</alwaysOn>
        <updateRate>18</updateRate>
        <cameraName>ovis/pt_grey_chameleon</cameraName>
        <imageTopicName>image_raw</imageTopicName>
        <cameraInfoTopicName>camera_info</cameraInfoTopicName>
        <frameName>camera</frameName>
        <hackBaseline>0.07</hackBaseline>
        <distortionK1>0.0</distortionK1>
        <distortionK2>0.0</distortionK2>
        <distortionK3>0.0</distortionK3>
        <distortionT1>0.0</distortionT1>
        <distortionT2>0.0</distortionT2>
      </plugin>
    </sensor>
  </gazebo>
  <!-- camera link -->
  <link name="ovis_camera">
    <inertial>
      <mass value=".1"/>
      <origin rpy="0 0 0" xyz="0 0 0"/>
      <inertia ixx="0" ixy="0.0" ixz="0.0" iyy="0" iyz="0.0" izz="0"/>
    </inertial>
    <!-- <visual>
            <geometry>
                <box size=".01 .01 .01"/>
            </geometry>
        </visual> -->
  </link>
  <link name="robotiq_arg2f_base_link">
    <inertial>
      <origin rpy="0 0 0" xyz="8.625E-08 -4.6583E-06 0.03145"/>
      <mass value="0.22652"/>
      <inertia ixx="0.00020005" ixy="-4.2442E-10" ixz="-2.9069E-10" iyy="0.00017832" iyz="-3.4402E-08" izz="0.00013478"/>
    </inertial>
    <visual>
      <origin rpy="0 0 0" xyz="0 0 0"/>
      <geometry>
        <mesh filename="package://robotiq_2f_140_gripper_visualization/meshes/visual/robotiq_arg2f_base_link.stl"/>
      </geometry>
      <material name="">
        <color rgba="0.1 0.1 0.1 1"/>
      </material>
    </visual>
    <collision>
      <origin rpy="0 0 0" xyz="0 0 0"/>
      <geometry>
        <mesh filename="package://robotiq_2f_140_gripper_visualization/meshes/collision/robotiq_arg2f_base_link.stl"/>
      </geometry>
    </collision>
  </link>
  <link name="left_outer_knuckle">
    <inertial>
      <origin rpy="0 0 0" xyz="-0.000200000000003065 0.0199435877845359 0.0292245259211331"/>
      <mass value="0.00853198276973456"/>
      <inertia ixx="2.89328108496468E-06" ixy="-1.57935047237397E-19" ixz="-1.93980378593255E-19" iyy="1.86719750325683E-06" iyz="-1.21858577871576E-06" izz="1.21905238907251E-06"/>
    </inertial>
    <visual>
      <origin rpy="0 0 0" xyz="0 0 0"/>
      <geometry>
        <mesh filename="package://robotiq_2f_140_gripper_visualization/meshes/visual/robotiq_arg2f_140_outer_knuckle.stl"/>
      </geometry>
      <material name="">
        <color rgba="0.792156862745098 0.819607843137255 0.933333333333333 1"/>
      </material>
    </visual>
    <collision>
      <origin rpy="0 0 0" xyz="0 0 0"/>
      <geometry>
        <mesh filename="package://robotiq_2f_140_gripper_visualization/meshes/collision/robotiq_arg2f_140_outer_knuckle.stl"/>
      </geometry>
    </collision>
  </link>
  <link name="left_outer_finger">
    <inertial>
      <origin rpy="0 0 0" xyz="0.00030115855001899 0.0373907951953854 -0.0208027427000385"/>
      <mass value="0.022614240507152"/>
      <inertia ixx="1.52518312458174E-05" ixy="9.76583423954399E-10" ixz="-5.43838577022588E-10" iyy="6.17694243867776E-06" iyz="6.78636130740228E-06" izz="1.16494917907219E-05"/>
    </inertial>
    <visual>
      <origin rpy="0 0 0" xyz="0 0 0"/>
      <geometry>
        <mesh filename="package://robotiq_2f_140_gripper_visualization/meshes/visual/robotiq_arg2f_140_outer_finger.stl"/>
      </geometry>
      <material name="">
        <color rgba="0.1 0.1 0.1 1"/>
      </material>
    </visual>
    <collision>
      <origin rpy="0 0 0" xyz="0 0 0"/>
      <geometry>
        <mesh filename="package://robotiq_2f_140_gripper_visualization/meshes/collision/robotiq_arg2f_140_outer_finger.stl"/>
      </geometry>
    </collision>
  </link>
  <link name="left_inner_finger">
    <inertial>
      <origin rpy="0 0 0" xyz="0.000299999999999317 0.0160078233491243 -0.0136945669206257"/>
      <mass value="0.0104003125914103"/>
      <inertia ixx="2.71909453810972E-06" ixy="1.35402465472579E-21" ixz="-7.1817349065269E-22" iyy="7.69100314106116E-07" iyz="6.74715432769696E-07" izz="2.30315190420171E-06"/>
    </inertial>
    <visual>
      <origin rpy="0 0 0" xyz="0 0 0"/>
      <geometry>
        <mesh filename="package://robotiq_2f_140_gripper_visualization/meshes/visual/robotiq_arg2f_140_inner_finger.stl"/>
      </geometry>
      <material name="">
        <color rgba="0.1 0.1 0.1 1"/>
      </material>
    </visual>
    <collision>
      <origin rpy="0 0 0" xyz="0 0 0"/>
      <geometry>
        <mesh filename="package://robotiq_2f_140_gripper_visualization/meshes/collision/robotiq_arg2f_140_inner_finger.stl"/>
      </geometry>
    </collision>
  </link>
  <link name="left_inner_finger_pad">
    <visual>
      <origin rpy="0 0 0" xyz="0 0 0"/>
      <geometry>
        <box size="0.027 0.065 0.0075"/>
      </geometry>
      <material name="">
        <color rgba="0.9 0.9 0.9 1"/>
      </material>
    </visual>
    <collision>
      <origin rpy="0 0 0" xyz="0 0 0"/>
      <geometry>
        <box size="0.03 0.07 0.0075"/>
      </geometry>
      <material name="">
        <color rgba="0.9 0.0 0.0 1"/>
      </material>
    </collision>
  </link>
  <link name="left_inner_knuckle">
    <inertial>
      <origin rpy="0 0 0" xyz="0.000123011831763771 0.0507850843201817 0.00103968640075166"/>
      <mass value="0.0271177346495152"/>
      <inertia ixx="2.61910379223783E-05" ixy="-2.43616858946494E-07" ixz="-6.37789906117123E-09" iyy="2.8270243746167E-06" iyz="-5.37200748039765E-07" izz="2.83695868220296E-05"/>
    </inertial>
    <visual>
      <origin rpy="0 0 0" xyz="0 0 0"/>
      <geometry>
        <mesh filename="package://robotiq_2f_140_gripper_visualization/meshes/visual/robotiq_arg2f_140_inner_knuckle.stl"/>
      </geometry>
      <material name="">
        <color rgba="0.1 0.1 0.1 1"/>
      </material>
    </visual>
    <collision>
      <origin rpy="0 0 0" xyz="0 0 0"/>
      <geometry>
        <mesh filename="package://robotiq_2f_140_gripper_visualization/meshes/collision/robotiq_arg2f_140_inner_knuckle.stl"/>
      </geometry>
    </collision>
  </link>
  <link name="right_outer_knuckle">
    <inertial>
      <origin rpy="0 0 0" xyz="-0.000200000000003065 0.0199435877845359 0.0292245259211331"/>
      <mass value="0.00853198276973456"/>
      <inertia ixx="2.89328108496468E-06" ixy="-1.57935047237397E-19" ixz="-1.93980378593255E-19" iyy="1.86719750325683E-06" iyz="-1.21858577871576E-06" izz="1.21905238907251E-06"/>
    </inertial>
    <visual>
      <origin rpy="0 0 0" xyz="0 0 0"/>
      <geometry>
        <mesh filename="package://robotiq_2f_140_gripper_visualization/meshes/visual/robotiq_arg2f_140_outer_knuckle.stl"/>
      </geometry>
      <material name="">
        <color rgba="0.792156862745098 0.819607843137255 0.933333333333333 1"/>
      </material>
    </visual>
    <collision>
      <origin rpy="0 0 0" xyz="0 0 0"/>
      <geometry>
        <mesh filename="package://robotiq_2f_140_gripper_visualization/meshes/collision/robotiq_arg2f_140_outer_knuckle.stl"/>
      </geometry>
    </collision>
  </link>
  <link name="right_outer_finger">
    <inertial>
      <origin rpy="0 0 0" xyz="0.00030115855001899 0.0373907951953854 -0.0208027427000385"/>
      <mass value="0.022614240507152"/>
      <inertia ixx="1.52518312458174E-05" ixy="9.76583423954399E-10" ixz="-5.43838577022588E-10" iyy="6.17694243867776E-06" iyz="6.78636130740228E-06" izz="1.16494917907219E-05"/>
    </inertial>
    <visual>
      <origin rpy="0 0 0" xyz="0 0 0"/>
      <geometry>
        <mesh filename="package://robotiq_2f_140_gripper_visualization/meshes/visual/robotiq_arg2f_140_outer_finger.stl"/>
      </geometry>
      <material name="">
        <color rgba="0.1 0.1 0.1 1"/>
      </material>
    </visual>
    <collision>
      <origin rpy="0 0 0" xyz="0 0 0"/>
      <geometry>
        <mesh filename="package://robotiq_2f_140_gripper_visualization/meshes/collision/robotiq_arg2f_140_outer_finger.stl"/>
      </geometry>
    </collision>
  </link>
  <link name="right_inner_finger">
    <inertial>
      <origin rpy="0 0 0" xyz="0.000299999999999317 0.0160078233491243 -0.0136945669206257"/>
      <mass value="0.0104003125914103"/>
      <inertia ixx="2.71909453810972E-06" ixy="1.35402465472579E-21" ixz="-7.1817349065269E-22" iyy="7.69100314106116E-07" iyz="6.74715432769696E-07" izz="2.30315190420171E-06"/>
    </inertial>
    <visual>
      <origin rpy="0 0 0" xyz="0 0 0"/>
      <geometry>
        <mesh filename="package://robotiq_2f_140_gripper_visualization/meshes/visual/robotiq_arg2f_140_inner_finger.stl"/>
      </geometry>
      <material name="">
        <color rgba="0.1 0.1 0.1 1"/>
      </material>
    </visual>
    <collision>
      <origin rpy="0 0 0" xyz="0 0 0"/>
      <geometry>
        <mesh filename="package://robotiq_2f_140_gripper_visualization/meshes/collision/robotiq_arg2f_140_inner_finger.stl"/>
      </geometry>
    </collision>
  </link>
  <link name="right_inner_finger_pad">
    <visual>
      <origin rpy="0 0 0" xyz="0 0 0"/>
      <geometry>
        <box size="0.027 0.065 0.0075"/>
      </geometry>
      <material name="">
        <color rgba="0.9 0.9 0.9 1"/>
      </material>
    </visual>
    <collision>
      <origin rpy="0 0 0" xyz="0 0 0"/>
      <geometry>
        <box size="0.03 0.07 0.0075"/>
      </geometry>
      <material name="">
        <color rgba="0.9 0.0 0.0 1"/>
      </material>
    </collision>
  </link>
  <link name="right_inner_knuckle">
    <inertial>
      <origin rpy="0 0 0" xyz="0.000123011831763771 0.0507850843201817 0.00103968640075166"/>
      <mass value="0.0271177346495152"/>
      <inertia ixx="2.61910379223783E-05" ixy="-2.43616858946494E-07" ixz="-6.37789906117123E-09" iyy="2.8270243746167E-06" iyz="-5.37200748039765E-07" izz="2.83695868220296E-05"/>
    </inertial>
    <visual>
      <origin rpy="0 0 0" xyz="0 0 0"/>
      <geometry>
        <mesh filename="package://robotiq_2f_140_gripper_visualization/meshes/visual/robotiq_arg2f_140_inner_knuckle.stl"/>
      </geometry>
      <material name="">
        <color rgba="0.1 0.1 0.1 1"/>
      </material>
    </visual>
    <collision>
      <origin rpy="0 0 0" xyz="0 0 0"/>
      <geometry>
        <mesh filename="package://robotiq_2f_140_gripper_visualization/meshes/collision/robotiq_arg2f_140_inner_knuckle.stl"/>
      </geometry>
    </collision>
  </link>
  <joint name="finger_joint" type="revolute">
    <origin rpy="2.29579632679 0 0" xyz="0 -0.030601 0.054905"/>
    <parent link="robotiq_arg2f_base_link"/>
    <child link="left_outer_knuckle"/>
    <axis xyz="-1 0 0"/>
    <limit effort="1000" lower="0" upper="0.7" velocity="2.0"/>
  </joint>
  <joint name="left_outer_finger_joint" type="fixed">
    <origin rpy="0 0 0" xyz="0 0.01821998610742 0.0260018192872234"/>
    <parent link="left_outer_knuckle"/>
    <child link="left_outer_finger"/>
    <axis xyz="1 0 0"/>
  </joint>
  <joint name="left_inner_knuckle_joint" type="revolute">
    <origin rpy="2.29579632679 0 0.0" xyz="0 -0.0127 0.06142"/>
    <parent link="robotiq_arg2f_base_link"/>
    <child link="left_inner_knuckle"/>
    <axis xyz="1 0 0"/>
    <limit effort="1000" lower="-0.8757" upper="0.8757" velocity="2.0"/>
    <mimic joint="finger_joint" multiplier="-1" offset="0"/>
  </joint>
  <joint name="left_inner_finger_joint" type="revolute">
    <origin rpy="-0.725 0 0" xyz="0 0.0817554015893473 -0.0282203446692936"/>
    <parent link="left_outer_finger"/>
    <child link="left_inner_finger"/>
    <axis xyz="1 0 0"/>
    <limit effort="1000" lower="-0.8757" upper="0.8757" velocity="2.0"/>
    <mimic joint="finger_joint" multiplier="1" offset="0"/>
  </joint>
  <joint name="left_inner_finger_pad_joint" type="fixed">
    <origin rpy="0 0 0" xyz="0 0.0457554015893473 -0.0272203446692936"/>
    <parent link="left_inner_finger"/>
    <child link="left_inner_finger_pad"/>
    <axis xyz="0 0 1"/>
  </joint>
  <joint name="right_outer_knuckle_joint" type="revolute">
    <origin rpy="2.29579632679 0 3.14159265359" xyz="0 0.030601 0.054905"/>
    <parent link="robotiq_arg2f_base_link"/>
    <child link="right_outer_knuckle"/>
    <axis xyz="1 0 0"/>
    <limit effort="1000" lower="-0.725" upper="0.725" velocity="2.0"/>
    <mimic joint="finger_joint" multiplier="-1" offset="0"/>
  </joint>
  <joint name="right_outer_finger_joint" type="fixed">
    <origin rpy="0 0 0" xyz="0 0.01821998610742 0.0260018192872234"/>
    <parent link="right_outer_knuckle"/>
    <child link="right_outer_finger"/>
    <axis xyz="1 0 0"/>
  </joint>
  <joint name="right_inner_knuckle_joint" type="revolute">
    <origin rpy="2.29579632679 0 -3.14159265359" xyz="0 0.0127 0.06142"/>
    <parent link="robotiq_arg2f_base_link"/>
    <child link="right_inner_knuckle"/>
    <axis xyz="1 0 0"/>
    <limit effort="1000" lower="-0.8757" upper="0.8757" velocity="2.0"/>
    <mimic joint="finger_joint" multiplier="-1" offset="0"/>
  </joint>
  <joint name="right_inner_finger_joint" type="revolute">
    <origin rpy="-0.725 0 0" xyz="0 0.0817554015893473 -0.0282203446692936"/>
    <parent link="right_outer_finger"/>
    <child link="right_inner_finger"/>
    <axis xyz="1 0 0"/>
    <limit effort="1000" lower="-0.8757" upper="0.8757" velocity="2.0"/>
    <mimic joint="finger_joint" multiplier="1" offset="0"/>
  </joint>
  <joint name="right_inner_finger_pad_joint" type="fixed">
    <origin rpy="0 0 0" xyz="0 0.0457554015893473 -0.0272203446692936"/>
    <parent link="right_inner_finger"/>
    <child link="right_inner_finger_pad"/>
    <axis xyz="0 0 1"/>
  </joint>
  <transmission name="finger_joint_trans">
    <type>transmission_interface/SimpleTransmission</type>
    <joint name="finger_joint">
      <hardwareInterface>PositionJointInterface</hardwareInterface>
    </joint>
    <actuator name="finger_joint_motor">
      <mechanicalReduction>1</mechanicalReduction>
    </actuator>
  </transmission>
  <!-- attach robotiq gripper to ovis flange -->
  <joint name="gripper_base" type="fixed">
    <parent link="ovis_link_tool0"/>
    <child link="robotiq_arg2f_base_link"/>
    <origin rpy="0 0 0" xyz="0 0 0"/>
  </joint>
  <link name="ovis_root"/>
  <!-- ros_control plugin -->
  <gazebo>
    <plugin filename="libgazebo_ros_control.so" name="gazebo_ros_control">
      <robotNamespace>ovis</robotNamespace>
      <robotSimType>gazebo_ros_control/DefaultRobotHWSim</robotSimType>
      <legacyModeNS>true</legacyModeNS>
    </plugin>
  </gazebo>
  <link name="ovis_link_base">
    <visual>
      <geometry>
        <mesh filename="package://ovis_description/meshes/visual/ovis_base.stl"/>
      </geometry>
      <origin rpy="1.57079632679 0 0" xyz="0 0 0"/>
    </visual>
    <collision>
      <geometry>
        <mesh filename="package://ovis_description/meshes/visual/ovis_base.stl"/>
      </geometry>
      <origin rpy="1.57079632679 0 0" xyz="0 0 0"/>
    </collision>
    <inertial>
      <mass value="1.53"/>
      <origin rpy="0 0 0" xyz="0 0 0.04385330"/>
      <inertia ixx="0.00320907" ixy="2e-008" ixz="2e-008" iyy="0.00321098" iyz="-6e-007" izz="0.0056695"/>
    </inertial>
  </link>
  <joint name="ovis_joint_base" type="fixed">
    <parent link="ovis_root"/>
    <child link="ovis_link_base"/>
    <axis xyz="0 0 0"/>
    <limit effort="0" lower="0" upper="0" velocity="0"/>
    <origin rpy="0 0 0" xyz="0 0 0"/>
    <dynamics damping="0.0" friction="0.0"/>
  </joint>
  <link name="ovis_link_1">
    <visual>
      <geometry>
        <mesh filename="package://ovis_description/meshes/visual/ovis_shoulder.stl"/>
      </geometry>
      <origin rpy="1.57079632679 0 0" xyz="0 0 0"/>
    </visual>
    <collision>
      <geometry>
        <mesh filename="package://ovis_description/meshes/visual/ovis_shoulder.stl"/>
      </geometry>
      <origin rpy="1.57079632679 0 0" xyz="0 0 0"/>
    </collision>
    <inertial>
      <mass value="1.2"/>
      <origin rpy="0 0 0" xyz="0 -0.0111 0.055"/>
      <inertia ixx="0.00248772" ixy="-1.6e-007" ixz="2.2e-007" iyy="0.0027245" iyz="-0.00031134" izz="0.00126329"/>
    </inertial>
  </link>
  <joint name="ovis_joint_1" type="continuous">
    <parent link="ovis_link_base"/>
    <child link="ovis_link_1"/>
    <axis xyz="0 0 1"/>
    <limit effort="40" lower="-12.5663706144" upper="12.5663706144" velocity="0.628318530718"/>
    <origin rpy="0 0 0" xyz="0 0 0.051"/>
    <dynamics damping="0.0" friction="0.0"/>
  </joint>
  <transmission name="ovis_joint_1_trans">
    <type>transmission_interface/SimpleTransmission</type>
    <joint name="ovis_joint_1">
      <hardwareInterface>hardware_interface/EffortJointInterface</hardwareInterface>
    </joint>
    <actuator name="ovis_joint_1_actuator">
      <hardwareInterface>hardware_interface/EffortJointInterface</hardwareInterface>
      <mechanicalReduction>160</mechanicalReduction>
    </actuator>
  </transmission>
  <!--For torque sensing in simulation-->
  <gazebo reference="ovis_joint_1">
    <provideFeedback>true</provideFeedback>
  </gazebo>
  <gazebo>
    <plugin filename="libgazebo_ros_ft_sensor.so" name="ft_sensor">
      <updateRate>30.0</updateRate>
      <topicName>ovis_joint_1_ft_sensor_topic</topicName>
      <jointName>ovis_joint_1</jointName>
    </plugin>
  </gazebo>
  <link name="ovis_link_2">
    <visual>
      <geometry>
        <mesh filename="package://ovis_description/meshes/visual/ovis_upper_arm.stl"/>
      </geometry>
      <origin rpy="0 0 0" xyz="0 0 0"/>
    </visual>
    <collision>
      <geometry>
        <mesh filename="package://ovis_description/meshes/visual/ovis_upper_arm.stl"/>
      </geometry>
      <origin rpy="0 0 0" xyz="0 0 0"/>
    </collision>
    <inertial>
      <mass value="1.3"/>
      <origin rpy="0 0 0" xyz="0 0.17553971 -0.00935895"/>
      <inertia ixx="0.03068681" ixy="1.76e-006" ixz="1e-007" iyy="0.00109408" iyz="0.00018345" izz="0.03103519"/>
    </inertial>
  </link>
  <joint name="ovis_joint_2" type="revolute">
    <parent link="ovis_link_1"/>
    <child link="ovis_link_2"/>
    <axis xyz="0 0 1"/>
    <limit effort="80" lower="-1.57079632679" upper="1.57079632679" velocity="0.628318530718"/>
    <origin rpy="1.57079632679 0 0" xyz="0 0 0.0889"/>
    <dynamics damping="0.0" friction="0.0"/>
  </joint>
  <transmission name="ovis_joint_2_trans">
    <type>transmission_interface/SimpleTransmission</type>
    <joint name="ovis_joint_2">
      <hardwareInterface>hardware_interface/EffortJointInterface</hardwareInterface>
    </joint>
    <actuator name="ovis_joint_2_actuator">
      <hardwareInterface>hardware_interface/EffortJointInterface</hardwareInterface>
      <mechanicalReduction>160</mechanicalReduction>
    </actuator>
  </transmission>
  <!--For torque sensing in simulation-->
  <gazebo reference="ovis_joint_2">
    <provideFeedback>true</provideFeedback>
  </gazebo>
  <gazebo>
    <plugin filename="libgazebo_ros_ft_sensor.so" name="ft_sensor">
      <updateRate>30.0</updateRate>
      <topicName>ovis_joint_2_ft_sensor_topic</topicName>
      <jointName>ovis_joint_2</jointName>
    </plugin>
  </gazebo>
  <link name="ovis_link_3">
    <visual>
      <geometry>
        <mesh filename="package://ovis_description/meshes/visual/ovis_elbow.stl"/>
      </geometry>
      <origin rpy="0 0 0" xyz="0 0 0"/>
    </visual>
    <collision>
      <geometry>
        <mesh filename="package://ovis_description/meshes/visual/ovis_elbow.stl"/>
      </geometry>
      <origin rpy="0 0 0" xyz="0 0 0"/>
    </collision>
    <inertial>
      <mass value="0.592"/>
      <origin rpy="0 0 0" xyz="0.03828435 0.01104986 0.00979839"/>
      <inertia ixx="0.00049443" ixy="0.00033167" ixz="-0.00021435" iyy="0.00147579" iyz="-6.259e-005" izz="0.0016474"/>
    </inertial>
  </link>
  <joint name="ovis_joint_3" type="revolute">
    <parent link="ovis_link_2"/>
    <child link="ovis_link_3"/>
    <axis xyz="0 0 1"/>
    <limit effort="40" lower="-1.57079632679" upper="1.57079632679" velocity="0.628318530718"/>
    <origin rpy="0 0 1.57079632679" xyz="0 0.465 0"/>
    <dynamics damping="0.0" friction="0.0"/>
  </joint>
  <transmission name="ovis_joint_3_trans">
    <type>transmission_interface/SimpleTransmission</type>
    <joint name="ovis_joint_3">
      <hardwareInterface>hardware_interface/EffortJointInterface</hardwareInterface>
    </joint>
    <actuator name="ovis_joint_3_actuator">
      <hardwareInterface>hardware_interface/EffortJointInterface</hardwareInterface>
      <mechanicalReduction>160</mechanicalReduction>
    </actuator>
  </transmission>
  <!--For torque sensing in simulation-->
  <gazebo reference="ovis_joint_3">
    <provideFeedback>true</provideFeedback>
  </gazebo>
  <gazebo>
    <plugin filename="libgazebo_ros_ft_sensor.so" name="ft_sensor">
      <updateRate>30.0</updateRate>
      <topicName>ovis_joint_3_ft_sensor_topic</topicName>
      <jointName>ovis_joint_3</jointName>
    </plugin>
  </gazebo>
  <link name="ovis_link_4">
    <visual>
      <geometry>
        <mesh filename="package://ovis_description/meshes/visual/ovis_forearm.stl"/>
      </geometry>
      <origin rpy="0 0 0" xyz="0 0 0"/>
    </visual>
    <collision>
      <geometry>
        <mesh filename="package://ovis_description/meshes/visual/ovis_forearm.stl"/>
      </geometry>
      <origin rpy="0 0 0" xyz="0 0 0"/>
    </collision>
    <inertial>
      <mass value="0.652"/>
      <origin rpy="0 0 0" xyz="0.00011113 0.12506366 0.00482529"/>
      <inertia ixx="0.00685564" ixy="-4.5e-006" ixz="-4.1e-007" iyy="0.00052903" iyz="0.00038138" izz="0.00686163"/>
    </inertial>
  </link>
  <joint name="ovis_joint_4" type="continuous">
    <parent link="ovis_link_3"/>
    <child link="ovis_link_4"/>
    <axis xyz="0 1 0"/>
    <limit effort="20" lower="-12.5663706144" upper="12.5663706144" velocity="0.837758040957"/>
    <origin rpy="0 0 0" xyz="0.0889 0.047625 0"/>
    <dynamics damping="0.0" friction="0.0"/>
  </joint>
  <transmission name="ovis_joint_4_trans">
    <type>transmission_interface/SimpleTransmission</type>
    <joint name="ovis_joint_4">
      <hardwareInterface>hardware_interface/EffortJointInterface</hardwareInterface>
    </joint>
    <actuator name="ovis_joint_4_actuator">
      <hardwareInterface>hardware_interface/EffortJointInterface</hardwareInterface>
      <mechanicalReduction>160</mechanicalReduction>
    </actuator>
  </transmission>
  <!--For torque sensing in simulation-->
  <gazebo reference="ovis_joint_4">
    <provideFeedback>true</provideFeedback>
  </gazebo>
  <gazebo>
    <plugin filename="libgazebo_ros_ft_sensor.so" name="ft_sensor">
      <updateRate>30.0</updateRate>
      <topicName>ovis_joint_4_ft_sensor_topic</topicName>
      <jointName>ovis_joint_4</jointName>
    </plugin>
  </gazebo>
  <link name="ovis_link_5">
    <visual>
      <geometry>
        <mesh filename="package://ovis_description/meshes/visual/ovis_wrist.stl"/>
      </geometry>
      <origin rpy="0 0 0" xyz="0 0 0"/>
    </visual>
    <collision>
      <geometry>
        <mesh filename="package://ovis_description/meshes/visual/ovis_wrist.stl"/>
      </geometry>
      <origin rpy="0 0 0" xyz="0 0 0"/>
    </collision>
    <inertial>
      <mass value="0.41555"/>
      <origin rpy="0 0 0" xyz="0.0 0.03086454 -0.00810577"/>
      <inertia ixx="0.00055858" ixy="-4.3e-007" ixz="-2.8e-007" iyy="0.00020049" iyz="9.39e-005" izz="0.00057545"/>
    </inertial>
  </link>
  <joint name="ovis_joint_5" type="revolute">
    <parent link="ovis_link_4"/>
    <child link="ovis_link_5"/>
    <axis xyz="0 0 1"/>
    <limit effort="20" lower="-1.57079632679" upper="1.57079632679" velocity="0.837758040957"/>
    <origin rpy="0 0 0" xyz="0 0.265 0"/>
    <dynamics damping="0.0" friction="0.0"/>
  </joint>
  <transmission name="ovis_joint_5_trans">
    <type>transmission_interface/SimpleTransmission</type>
    <joint name="ovis_joint_5">
      <hardwareInterface>hardware_interface/EffortJointInterface</hardwareInterface>
    </joint>
    <actuator name="ovis_joint_5_actuator">
      <hardwareInterface>hardware_interface/EffortJointInterface</hardwareInterface>
      <mechanicalReduction>160</mechanicalReduction>
    </actuator>
  </transmission>
  <!--For torque sensing in simulation-->
  <gazebo reference="ovis_joint_5">
    <provideFeedback>true</provideFeedback>
  </gazebo>
  <gazebo>
    <plugin filename="libgazebo_ros_ft_sensor.so" name="ft_sensor">
      <updateRate>30.0</updateRate>
      <topicName>ovis_joint_5_ft_sensor_topic</topicName>
      <jointName>ovis_joint_5</jointName>
    </plugin>
  </gazebo>
  <link name="ovis_link_6">
    <visual>
      <geometry>
        <mesh filename="package://ovis_description/meshes/visual/ovis_flange.stl"/>
      </geometry>
      <origin rpy="0 0 0" xyz="0 0 0"/>
    </visual>
    <collision>
      <geometry>
        <mesh filename="package://ovis_description/meshes/collision/ovis_flange.stl"/>
      </geometry>
      <origin rpy="0 0 0" xyz="0 0 0"/>
    </collision>
    <inertial>
      <mass value="0.6448"/>
      <origin rpy="0 0 0" xyz="-0.00120093 0.06932019 -0.00169931"/>
      <inertia ixx="0.00326124" ixy="-1.39e-005" ixz="-1.38e-006" iyy="0.00125679" iyz="1.69e-005" izz="0.00393291"/>
    </inertial>
  </link>
  <joint name="ovis_joint_6" type="continuous">
    <parent link="ovis_link_5"/>
    <child link="ovis_link_6"/>
    <axis xyz="0 0 1"/>
    <limit effort="20" lower="-6.28318530718" upper="6.28318530718" velocity="0.837758040957"/>
    <origin rpy="1.57079632679 1.57079632679 0" xyz="0 0.0762 0"/>
    <dynamics damping="0.0" friction="0.0"/>
  </joint>
  <transmission name="ovis_joint_6_trans">
    <type>transmission_interface/SimpleTransmission</type>
    <joint name="ovis_joint_6">
      <hardwareInterface>hardware_interface/EffortJointInterface</hardwareInterface>
    </joint>
    <actuator name="ovis_joint_6_actuator">
      <hardwareInterface>hardware_interface/EffortJointInterface</hardwareInterface>
      <mechanicalReduction>160</mechanicalReduction>
    </actuator>
  </transmission>
  <!--For torque sensing in simulation-->
  <gazebo reference="ovis_joint_6">
    <provideFeedback>true</provideFeedback>
  </gazebo>
  <gazebo>
    <plugin filename="libgazebo_ros_ft_sensor.so" name="ft_sensor">
      <updateRate>30.0</updateRate>
      <topicName>ovis_joint_6_ft_sensor_topic</topicName>
      <jointName>ovis_joint_6</jointName>
    </plugin>
  </gazebo>
  <link name="ovis_link_tool0"/>
  <joint name="ovis_joint_tool0" type="fixed">
    <parent link="ovis_link_6"/>
    <child link="ovis_link_tool0"/>
    <axis xyz="0 0 0"/>
    <limit effort="2000" lower="0" upper="0" velocity="1"/>
    <origin rpy="0 3.14159265359 1.57079632679" xyz="0 0 -0.09215"/>
  </joint>
  <link name="ovis_end_effector"/>
  <joint name="ovis_joint_end_effector" type="fixed">
    <parent link="ovis_link_tool0"/>
    <child link="ovis_end_effector"/>
    <axis xyz="0 0 0"/>
    <limit effort="2000" lower="0" upper="0" velocity="1"/>
    <origin rpy="0 0 0" xyz="0 0 0.1778"/>
  </joint>
  <joint name="ovis_camera" type="fixed">
    <parent link="ovis_link_6"/>
    <child link="ovis_camera"/>
    <axis xyz="0 0 1"/>
    <limit effort="2000" lower="0" upper="0" velocity="1"/>
    <origin rpy="0 1.57079632679 1.57079632679" xyz="0 0.091842 -0.0732"/>
  </joint>
  <!-- for gazebo -->
  <link name="world"/>
  <joint name="connect_root_and_world" type="fixed">
    <child link="ovis_root"/>
    <parent link="world"/>
    <origin rpy="0 0 0" xyz="0 0 0"/>
  </joint>
</robot>
